<?xml version="1.0"?>
<robot xmlns:xacro="http://ros.org/wiki/xacro">
    <xacro:macro name="carriage">


        <link name="base_link">
            <visual>
                <geometry>
                    <mesh filename="package://robot_description/meshes/Base.STL"/>
                </geometry>
                <material name="light_green">
                    <color rgba="1 0.7 0.7 1.0"/>
                </material>
            </visual>
            <collision>
                <geometry>
                    <mesh filename="package://robot_description/meshes/Base.STL"/>
                </geometry>
            </collision>
            <inertial>
                <origin xyz="0 0 0" rpy="0 0 0" />
                <mass value="1" />
                <inertia
                        ixx="1.0" ixy="0.0" ixz="0.0"
                        iyy="1.0" iyz="0.0"
                        izz="1.0" />
            </inertial>
        </link>

        <link name="carriage_link">
            <visual>
                <geometry>
                    <mesh filename="package://robot_description/meshes/Carriage.STL"/>
                </geometry>
                <material name="purple">
                    <color rgba="0.7 0.7 1.0 1.0"/>
                </material>
            </visual>
            <collision>
                <geometry>
                    <mesh filename="package://robot_description/meshes/Carriage.STL"/>
                </geometry>
            </collision>
            <inertial>
                <origin xyz="0 0 0" rpy="0 0 0" />
                <mass value="1" />
                <inertia
                        ixx="1.0" ixy="0.0" ixz="0.0"
                        iyy="1.0" iyz="0.0"
                        izz="1.0" />
            </inertial>
        </link>
        <joint name="carriage_joint" type="prismatic">
            <origin xyz="0 0.06 0" rpy="0 ${0.5*pi} 0 "/>
            <parent link="base_link"/>
            <child link="carriage_link"/>
            <limit effort="150.0" lower="-0.3" upper="0.3" velocity="0.5"/>
            <axis xyz="0 0 1"/>
        </joint>

        <transmission name="carriage_trans">
            <type>transmission_interface/SimpleTransmission</type>
            <joint name="carriage_joint">
                <hardwareInterface>hardware_interface/PositionJointInterface</hardwareInterface>
            </joint>
            <actuator name="carriage_joint_motor">
                <hardwareInterface>hardware_interface/PositionJointInterface</hardwareInterface>
                <mechanicalReduction>1</mechanicalReduction>
            </actuator>
        </transmission>

        <gazebo reference="carriage_link">
            <selfCollide>true</selfCollide>
        </gazebo>
    </xacro:macro>
</robot>