<?xml version="1.0"?>
<robot xmlns:xacro="http://ros.org/wiki/xacro">
    <xacro:macro name="robot">
        <joint name="robot_base_joint" type="revolute">
            <axis xyz="0 1 0"/>
            <limit effort="150.0" lower="${-2*pi}" upper="${2*pi}" velocity="${pi}"/>
            <origin xyz="0 0.14 0" rpy="0 0 0 "/>
            <parent link="carriage_link"/>
            <child link="robot_base_link"/>
        </joint>

        <link name="robot_base_link">
            <visual>
                <geometry>
                    <mesh filename="package://robot_description/meshes/Robot_Pan.STL"/>
                </geometry>
                <material name="dark_purple">
                    <color rgba="0.7 0 0.7 1.0"/>
                </material>
            </visual>
            <collision>
                <geometry>
                    <mesh filename="package://robot_description/meshes/Robot_Pan.STL"/>
                </geometry>
            </collision>
            <inertial>
                <origin xyz="0 0 0" rpy="0 0 0" />
                <mass value="1" />
                <inertia
                        ixx="1.0" ixy="0.0" ixz="0.0"
                        iyy="1.0" iyz="0.0"
                        izz="1.0" />
            </inertial>
        </link>

        <transmission name="robot_base_trans">
            <type>transmission_interface/SimpleTransmission</type>
            <joint name="robot_base_joint">
                <hardwareInterface>hardware_interface/PositionJointInterface</hardwareInterface>
            </joint>
            <actuator name="robot_base_motor">
                <hardwareInterface>hardware_interface/PositionJointInterface</hardwareInterface>
                <mechanicalReduction>1</mechanicalReduction>
            </actuator>
        </transmission>

        <gazebo reference="robot_base_link">
            <selfCollide>true</selfCollide>
        </gazebo>

        <joint name="robot_arm_joint" type="revolute">
            <axis xyz="0 0 1"/>
            <limit effort="150.0" lower="${-2*pi}" upper="${2*pi}" velocity="${pi}"/>
            <origin xyz="0 0 0" rpy="${pi} ${0.5*pi} 0"/>
            <parent link="robot_base_link"/>
            <child link="robot_arm_link"/>
        </joint>

        <link name="robot_arm_link">
            <visual>
                <geometry>
                    <mesh filename="package://robot_description/meshes/Robot_Arm.STL"/>
                </geometry>
                <material name="green">
                    <color rgba="0.7 1 0.4 1.0"/>
                </material>
            </visual>
            <collision>
                <geometry>
                    <mesh filename="package://robot_description/meshes/Robot_Arm.STL"/>
                </geometry>
            </collision>
            <inertial>
                <origin xyz="0 0 0" rpy="0 0 0" />
                <mass value="1" />
                <inertia
                        ixx="1.0" ixy="0.0" ixz="0.0"
                        iyy="1.0" iyz="0.0"
                        izz="1.0" />
            </inertial>
        </link>

        <transmission name="robot_arm_trans">
            <type>transmission_interface/SimpleTransmission</type>
            <joint name="robot_arm_joint">
                <hardwareInterface>hardware_interface/PositionJointInterface</hardwareInterface>
            </joint>
            <actuator name="robot_arm_motor">
                <hardwareInterface>hardware_interface/PositionJointInterface</hardwareInterface>
                <mechanicalReduction>1</mechanicalReduction>
            </actuator>
        </transmission>

        <gazebo reference="robot_arm_link">
            <selfCollide>true</selfCollide>
        </gazebo>

        <joint name="robot_forearm_joint" type="revolute">
            <axis xyz="0 0 1"/>
            <limit effort="150.0" lower="${-0.5*pi}" upper="${0.5*pi}" velocity="${pi}"/>
            <origin xyz="0 -0.5 0" rpy="0 0 ${pi}"/>
            <parent link="robot_arm_link"/>
            <child link="robot_forearm_link"/>
        </joint>

        <link name="robot_forearm_link">
            <visual>
                <geometry>
                    <mesh filename="package://robot_description/meshes/Robot_Forearm.STL"/>
                </geometry>
                <material name="blue">
                    <color rgba="0.4 0.4 1.0 1.0"/>
                </material>
            </visual>
            <collision>
                <geometry>
                    <mesh filename="package://robot_description/meshes/Robot_Forearm.STL"/>
                </geometry>
            </collision>
            <inertial>
                <origin xyz="0 0 0" rpy="0 0 0" />
                <mass value="1" />
                <inertia
                        ixx="1.0" ixy="0.0" ixz="0.0"
                        iyy="1.0" iyz="0.0"
                        izz="1.0" />
            </inertial>
        </link>

        <transmission name="robot_forearm_trans">
            <type>transmission_interface/SimpleTransmission</type>
            <joint name="robot_forearm_joint">
                <hardwareInterface>hardware_interface/PositionJointInterface</hardwareInterface>
            </joint>
            <actuator name="robot_forearm_motor">
                <hardwareInterface>hardware_interface/PositionJointInterface</hardwareInterface>
                <mechanicalReduction>1</mechanicalReduction>
            </actuator>
        </transmission>

        <gazebo reference="robot_forearm_link">
            <selfCollide>true</selfCollide>
        </gazebo>

        <joint name="robot_wrist_joint" type="revolute">
            <axis xyz="0 1 0"/>
            <limit effort="150.0" lower="${-2*pi}" upper="${2*pi}" velocity="${pi}"/>
            <origin xyz="0 0.17 0" rpy="0 0 0"/>
            <parent link="robot_forearm_link"/>
            <child link="robot_wrist_link"/>
        </joint>

        <link name="robot_wrist_link">
            <visual>
                <geometry>
                    <mesh filename="package://robot_description/meshes/Robot_End_Effector.STL"/>
                </geometry>
            </visual>
            <collision>
                <geometry>
                    <mesh filename="package://robot_description/meshes/Robot_End_Effector.STL"/>
                </geometry>
            </collision>
            <inertial>
                <origin xyz="0 0 0" rpy="0 0 0" />
                <mass value="1" />
                <inertia
                        ixx="1.0" ixy="0.0" ixz="0.0"
                        iyy="1.0" iyz="0.0"
                        izz="1.0" />
            </inertial>
        </link>

        <transmission name="robot_wrist_trans">
            <type>transmission_interface/SimpleTransmission</type>
            <joint name="robot_wrist_joint">
                <hardwareInterface>hardware_interface/PositionJointInterface</hardwareInterface>
            </joint>
            <actuator name="robot_wrist_motor">
                <hardwareInterface>hardware_interface/PositionJointInterface</hardwareInterface>
                <mechanicalReduction>1</mechanicalReduction>
            </actuator>
        </transmission>

        <gazebo reference="robot_wrist_link">
            <selfCollide>true</selfCollide>
        </gazebo>

        <joint name="end_effector" type="fixed">
            <origin xyz="0 0.035 0" rpy="0 0 0"/>
            <parent link="robot_wrist_link"/>
            <child link="end_effector_link"/>
        </joint>

        <link name="end_effector_link"/>

        <link name="cam_left"/>
        <joint name="cam_left_joint" type="fixed">
            <origin xyz="0.0415 0.011 0.0135" rpy="-${0.5*pi} ${0.5*pi} 0"/>
            <parent link="robot_wrist_link"/>
            <child link="cam_left"/>
        </joint>

        <link name="cam_right"/>
        <joint name="cam_right_joint" type="fixed">
            <origin xyz="0.0415 0.011 -0.0135" rpy="-${0.5*pi} ${0.5*pi} 0"/>
            <parent link="robot_wrist_link"/>
            <child link="cam_right"/>
        </joint>

    </xacro:macro>
</robot>