<?xml version="1.0"?>
<robot xmlns:xacro="http://ros.org/wiki/xacro">
    <xacro:macro name="robot">
        <joint name="robot_base_joint" type="revolute">
            <axis xyz="0 1 0"/>
            <limit effort="150.0" lower="${-2*pi}" upper="${2*pi}" velocity="${pi}"/>
            <origin xyz="0 0.14 0" rpy="0 0 0 "/>
            <parent link="carriage_link"/>
            <child link="robot_base_link"/>
        </joint>

        <link name="robot_base_link">
            <visual>
                <geometry>
                    <mesh filename="package://robot_description/meshes/Robot_Pan.STL"/>
                </geometry>
            </visual>
            <collision>
                <geometry>
                    <mesh filename="package://robot_description/meshes/Robot_Pan.STL"/>
                </geometry>
            </collision>
        </link>

        <joint name="robot_arm_joint" type="revolute">
            <axis xyz="0 0 1"/>
            <limit effort="150.0" lower="${-2*pi}" upper="${2*pi}" velocity="${pi}"/>
            <origin xyz="0 0 0" rpy="${pi} ${0.5*pi} 0"/>
            <parent link="robot_base_link"/>
            <child link="robot_arm_link"/>
        </joint>

        <link name="robot_arm_link">
            <visual>
                <geometry>
                    <mesh filename="package://robot_description/meshes/Robot_Arm.STL"/>
                </geometry>
            </visual>
            <collision>
                <geometry>
                    <mesh filename="package://robot_description/meshes/Robot_Arm.STL"/>
                </geometry>
            </collision>
        </link>

        <joint name="robot_forearm_joint" type="revolute">
            <axis xyz="0 0 1"/>
            <limit effort="150.0" lower="${-0.5*pi}" upper="${0.5*pi}" velocity="${pi}"/>
            <origin xyz="0 -0.5 0" rpy="0 0 ${pi}"/>
            <parent link="robot_arm_link"/>
            <child link="robot_forearm_link"/>
        </joint>

        <link name="robot_forearm_link">
            <visual>
                <geometry>
                    <mesh filename="package://robot_description/meshes/Robot_Forearm.STL"/>
                </geometry>
            </visual>
            <collision>
                <geometry>
                    <mesh filename="package://robot_description/meshes/Robot_Forearm.STL"/>
                </geometry>
            </collision>
        </link>

        <joint name="robot_wrist_joint" type="revolute">
            <axis xyz="0 1 0"/>
            <limit effort="150.0" lower="${-2*pi}" upper="${2*pi}" velocity="${pi}"/>
            <origin xyz="0 0.17 0" rpy="0 0 0"/>
            <parent link="robot_forearm_link"/>
            <child link="robot_wrist_link"/>
        </joint>

        <link name="robot_wrist_link">
            <visual>
                <geometry>
                    <mesh filename="package://robot_description/meshes/Robot_End_Effector.STL"/>
                </geometry>
            </visual>
            <collision>
                <geometry>
                    <mesh filename="package://robot_description/meshes/Robot_End_Effector.STL"/>
                </geometry>
            </collision>
        </link>

        <joint name="end_effector" type="fixed">
            <origin xyz="0 0.035 0" rpy="0 0 0"/>
            <parent link="robot_wrist_link"/>
            <child link="end_effector_link"/>
        </joint>

        <link name="end_effector_link"/>

    </xacro:macro>
</robot>